2025-09-12 22:52:25,028 : ERROR : COINBASE: Failed to parse symbol information: 401 Client Error: Unauthorized for url: https://api.coinbase.com/api/v3/brokerage/products
Traceback (most recent call last):
  File "/Library/Frameworks/Python.framework/Versions/3.12/lib/python3.12/site-packages/cryptofeed/exchange.py", line 103, in symbol_mapping
    data.append(cls.http_sync.read(addr, json=True, headers=headers, uuid=cls.id))
                ^^^^^^^^^^^^^^^^^^^^^^^^^^^^^^^^^^^^^^^^^^^^^^^^^^^^^^^^^^^^^^^^^
  File "/Library/Frameworks/Python.framework/Versions/3.12/lib/python3.12/site-packages/cryptofeed/connection.py", line 57, in read
    return self.process_response(r, address, json=json, text=text, uuid=uuid)
           ^^^^^^^^^^^^^^^^^^^^^^^^^^^^^^^^^^^^^^^^^^^^^^^^^^^^^^^^^^^^^^^^^^
  File "/Library/Frameworks/Python.framework/Versions/3.12/lib/python3.12/site-packages/cryptofeed/connection.py", line 47, in process_response
    r.raise_for_status()
  File "/Library/Frameworks/Python.framework/Versions/3.12/lib/python3.12/site-packages/requests/models.py", line 1024, in raise_for_status
    raise HTTPError(http_error_msg, response=self)
requests.exceptions.HTTPError: 401 Client Error: Unauthorized for url: https://api.coinbase.com/api/v3/brokerage/products
2025-09-12 22:58:29,809 : ERROR : COINBASE: Failed to parse symbol information: 401 Client Error: Unauthorized for url: https://api.coinbase.com/api/v3/brokerage/products
Traceback (most recent call last):
  File "/Users/joshuamiller/Developer/llm_crypto_bot/venv/lib/python3.12/site-packages/cryptofeed/exchange.py", line 103, in symbol_mapping
    data.append(cls.http_sync.read(addr, json=True, headers=headers, uuid=cls.id))
                ^^^^^^^^^^^^^^^^^^^^^^^^^^^^^^^^^^^^^^^^^^^^^^^^^^^^^^^^^^^^^^^^^
  File "/Users/joshuamiller/Developer/llm_crypto_bot/venv/lib/python3.12/site-packages/cryptofeed/connection.py", line 57, in read
    return self.process_response(r, address, json=json, text=text, uuid=uuid)
           ^^^^^^^^^^^^^^^^^^^^^^^^^^^^^^^^^^^^^^^^^^^^^^^^^^^^^^^^^^^^^^^^^^
  File "/Users/joshuamiller/Developer/llm_crypto_bot/venv/lib/python3.12/site-packages/cryptofeed/connection.py", line 47, in process_response
    r.raise_for_status()
  File "/Users/joshuamiller/Developer/llm_crypto_bot/venv/lib/python3.12/site-packages/requests/models.py", line 1026, in raise_for_status
    raise HTTPError(http_error_msg, response=self)
requests.exceptions.HTTPError: 401 Client Error: Unauthorized for url: https://api.coinbase.com/api/v3/brokerage/products
2025-09-12 23:00:44,055 : ERROR : COINBASE: Failed to parse symbol information: 401 Client Error: Unauthorized for url: https://api.coinbase.com/api/v3/brokerage/products
Traceback (most recent call last):
  File "/Users/joshuamiller/Developer/llm_crypto_bot/venv/lib/python3.12/site-packages/cryptofeed/exchange.py", line 103, in symbol_mapping
    data.append(cls.http_sync.read(addr, json=True, headers=headers, uuid=cls.id))
                ^^^^^^^^^^^^^^^^^^^^^^^^^^^^^^^^^^^^^^^^^^^^^^^^^^^^^^^^^^^^^^^^^
  File "/Users/joshuamiller/Developer/llm_crypto_bot/venv/lib/python3.12/site-packages/cryptofeed/connection.py", line 57, in read
    return self.process_response(r, address, json=json, text=text, uuid=uuid)
           ^^^^^^^^^^^^^^^^^^^^^^^^^^^^^^^^^^^^^^^^^^^^^^^^^^^^^^^^^^^^^^^^^^
  File "/Users/joshuamiller/Developer/llm_crypto_bot/venv/lib/python3.12/site-packages/cryptofeed/connection.py", line 47, in process_response
    r.raise_for_status()
  File "/Users/joshuamiller/Developer/llm_crypto_bot/venv/lib/python3.12/site-packages/requests/models.py", line 1026, in raise_for_status
    raise HTTPError(http_error_msg, response=self)
requests.exceptions.HTTPError: 401 Client Error: Unauthorized for url: https://api.coinbase.com/api/v3/brokerage/products
2025-09-13 06:54:16,669 : ERROR : COINBASE: Failed to parse symbol information: HTTPSConnectionPool(host='api.coinbase.com', port=443): Max retries exceeded with url: /api/v3/brokerage/products (Caused by NameResolutionError("<urllib3.connection.HTTPSConnection object at 0x10c0f7610>: Failed to resolve 'api.coinbase.com' ([Errno 8] nodename nor servname provided, or not known)"))
Traceback (most recent call last):
  File "/Users/joshuamiller/Developer/.venv/lib/python3.13/site-packages/urllib3/connection.py", line 198, in _new_conn
    sock = connection.create_connection(
        (self._dns_host, self.port),
    ...<2 lines>...
        socket_options=self.socket_options,
    )
  File "/Users/joshuamiller/Developer/.venv/lib/python3.13/site-packages/urllib3/util/connection.py", line 60, in create_connection
    for res in socket.getaddrinfo(host, port, family, socket.SOCK_STREAM):
               ~~~~~~~~~~~~~~~~~~^^^^^^^^^^^^^^^^^^^^^^^^^^^^^^^^^^^^^^^^
  File "/opt/homebrew/Cellar/python@3.13/3.13.5/Frameworks/Python.framework/Versions/3.13/lib/python3.13/socket.py", line 977, in getaddrinfo
    for res in _socket.getaddrinfo(host, port, family, type, proto, flags):
               ~~~~~~~~~~~~~~~~~~~^^^^^^^^^^^^^^^^^^^^^^^^^^^^^^^^^^^^^^^^
socket.gaierror: [Errno 8] nodename nor servname provided, or not known

The above exception was the direct cause of the following exception:

Traceback (most recent call last):
  File "/Users/joshuamiller/Developer/.venv/lib/python3.13/site-packages/urllib3/connectionpool.py", line 787, in urlopen
    response = self._make_request(
        conn,
    ...<10 lines>...
        **response_kw,
    )
  File "/Users/joshuamiller/Developer/.venv/lib/python3.13/site-packages/urllib3/connectionpool.py", line 488, in _make_request
    raise new_e
  File "/Users/joshuamiller/Developer/.venv/lib/python3.13/site-packages/urllib3/connectionpool.py", line 464, in _make_request
    self._validate_conn(conn)
    ~~~~~~~~~~~~~~~~~~~^^^^^^
  File "/Users/joshuamiller/Developer/.venv/lib/python3.13/site-packages/urllib3/connectionpool.py", line 1093, in _validate_conn
    conn.connect()
    ~~~~~~~~~~~~^^
  File "/Users/joshuamiller/Developer/.venv/lib/python3.13/site-packages/urllib3/connection.py", line 753, in connect
    self.sock = sock = self._new_conn()
                       ~~~~~~~~~~~~~~^^
  File "/Users/joshuamiller/Developer/.venv/lib/python3.13/site-packages/urllib3/connection.py", line 205, in _new_conn
    raise NameResolutionError(self.host, self, e) from e
urllib3.exceptions.NameResolutionError: <urllib3.connection.HTTPSConnection object at 0x10c0f7610>: Failed to resolve 'api.coinbase.com' ([Errno 8] nodename nor servname provided, or not known)

The above exception was the direct cause of the following exception:

Traceback (most recent call last):
  File "/Users/joshuamiller/Developer/.venv/lib/python3.13/site-packages/requests/adapters.py", line 644, in send
    resp = conn.urlopen(
        method=request.method,
    ...<9 lines>...
        chunked=chunked,
    )
  File "/Users/joshuamiller/Developer/.venv/lib/python3.13/site-packages/urllib3/connectionpool.py", line 841, in urlopen
    retries = retries.increment(
        method, url, error=new_e, _pool=self, _stacktrace=sys.exc_info()[2]
    )
  File "/Users/joshuamiller/Developer/.venv/lib/python3.13/site-packages/urllib3/util/retry.py", line 519, in increment
    raise MaxRetryError(_pool, url, reason) from reason  # type: ignore[arg-type]
    ^^^^^^^^^^^^^^^^^^^^^^^^^^^^^^^^^^^^^^^^^^^^^^^^^^^
urllib3.exceptions.MaxRetryError: HTTPSConnectionPool(host='api.coinbase.com', port=443): Max retries exceeded with url: /api/v3/brokerage/products (Caused by NameResolutionError("<urllib3.connection.HTTPSConnection object at 0x10c0f7610>: Failed to resolve 'api.coinbase.com' ([Errno 8] nodename nor servname provided, or not known)"))

During handling of the above exception, another exception occurred:

Traceback (most recent call last):
  File "/Users/joshuamiller/Developer/.venv/lib/python3.13/site-packages/cryptofeed/exchange.py", line 103, in symbol_mapping
    data.append(cls.http_sync.read(addr, json=True, headers=headers, uuid=cls.id))
                ~~~~~~~~~~~~~~~~~~^^^^^^^^^^^^^^^^^^^^^^^^^^^^^^^^^^^^^^^^^^^^^^^
  File "/Users/joshuamiller/Developer/.venv/lib/python3.13/site-packages/cryptofeed/connection.py", line 56, in read
    r = requests.get(address, headers=headers, params=params)
  File "/Users/joshuamiller/Developer/.venv/lib/python3.13/site-packages/requests/api.py", line 73, in get
    return request("get", url, params=params, **kwargs)
  File "/Users/joshuamiller/Developer/.venv/lib/python3.13/site-packages/requests/api.py", line 59, in request
    return session.request(method=method, url=url, **kwargs)
           ~~~~~~~~~~~~~~~^^^^^^^^^^^^^^^^^^^^^^^^^^^^^^^^^^
  File "/Users/joshuamiller/Developer/.venv/lib/python3.13/site-packages/requests/sessions.py", line 589, in request
    resp = self.send(prep, **send_kwargs)
  File "/Users/joshuamiller/Developer/.venv/lib/python3.13/site-packages/requests/sessions.py", line 703, in send
    r = adapter.send(request, **kwargs)
  File "/Users/joshuamiller/Developer/.venv/lib/python3.13/site-packages/requests/adapters.py", line 677, in send
    raise ConnectionError(e, request=request)
requests.exceptions.ConnectionError: HTTPSConnectionPool(host='api.coinbase.com', port=443): Max retries exceeded with url: /api/v3/brokerage/products (Caused by NameResolutionError("<urllib3.connection.HTTPSConnection object at 0x10c0f7610>: Failed to resolve 'api.coinbase.com' ([Errno 8] nodename nor servname provided, or not known)"))
2025-09-13 19:49:38,015 : ERROR : COINBASE: Failed to parse symbol information: 401 Client Error: Unauthorized for url: https://api.coinbase.com/api/v3/brokerage/products
Traceback (most recent call last):
  File "/Library/Frameworks/Python.framework/Versions/3.12/lib/python3.12/site-packages/cryptofeed/exchange.py", line 103, in symbol_mapping
    data.append(cls.http_sync.read(addr, json=True, headers=headers, uuid=cls.id))
                ^^^^^^^^^^^^^^^^^^^^^^^^^^^^^^^^^^^^^^^^^^^^^^^^^^^^^^^^^^^^^^^^^
  File "/Library/Frameworks/Python.framework/Versions/3.12/lib/python3.12/site-packages/cryptofeed/connection.py", line 57, in read
    return self.process_response(r, address, json=json, text=text, uuid=uuid)
           ^^^^^^^^^^^^^^^^^^^^^^^^^^^^^^^^^^^^^^^^^^^^^^^^^^^^^^^^^^^^^^^^^^
  File "/Library/Frameworks/Python.framework/Versions/3.12/lib/python3.12/site-packages/cryptofeed/connection.py", line 47, in process_response
    r.raise_for_status()
  File "/Library/Frameworks/Python.framework/Versions/3.12/lib/python3.12/site-packages/requests/models.py", line 1024, in raise_for_status
    raise HTTPError(http_error_msg, response=self)
requests.exceptions.HTTPError: 401 Client Error: Unauthorized for url: https://api.coinbase.com/api/v3/brokerage/products
